2024-04-08 06:48:50,516 INFO    StreamThr :16344 [internal.py:wandb_internal():86] W&B internal server running at pid: 16344, started at: 2024-04-08 06:48:50.515033
2024-04-08 06:48:50,519 DEBUG   HandlerThread:16344 [handler.py:handle_request():146] handle_request: status
2024-04-08 06:48:50,522 INFO    WriterThread:16344 [datastore.py:open_for_write():87] open: C:\Users\sazegar\mir\logic\core\wandb\run-20240408_064850-woc89rfs\run-woc89rfs.wandb
2024-04-08 06:48:50,524 DEBUG   SenderThread:16344 [sender.py:send():378] send: header
2024-04-08 06:48:50,562 DEBUG   SenderThread:16344 [sender.py:send():378] send: run
2024-04-08 06:48:51,020 ERROR   SenderThread:16344 [internal_api.py:execute():373] 403 response executing GraphQL.
2024-04-08 06:48:51,020 ERROR   SenderThread:16344 [internal_api.py:execute():374] 
<html><head>
<meta http-equiv="content-type" content="text/html;charset=utf-8">
<title>403 Forbidden</title>
</head>
<body text=#000000 bgcolor=#ffffff>
<h1>Error: Forbidden</h1>
<h2>Your client does not have permission to get URL <code>/graphql</code> from this server.</h2>
<h2></h2>
</body></html>

2024-04-08 06:48:51,020 ERROR   SenderThread:16344 [sender.py:send_run():950] It appears that you do not have permission to access the requested resource. Please reach out to the project owner to grant you access. If you have the correct permissions, verify that there are no issues with your networking setup.(Error 403: Forbidden)
Traceback (most recent call last):
  File "C:\Users\sazegar\AppData\Local\Programs\Python\Python38\lib\site-packages\wandb\sdk\lib\retry.py", line 131, in __call__
    result = self._call_fn(*args, **kwargs)
  File "C:\Users\sazegar\AppData\Local\Programs\Python\Python38\lib\site-packages\wandb\sdk\internal\internal_api.py", line 369, in execute
    return self.client.execute(*args, **kwargs)  # type: ignore
  File "C:\Users\sazegar\AppData\Local\Programs\Python\Python38\lib\site-packages\wandb\vendor\gql-0.2.0\wandb_gql\client.py", line 52, in execute
    result = self._get_result(document, *args, **kwargs)
  File "C:\Users\sazegar\AppData\Local\Programs\Python\Python38\lib\site-packages\wandb\vendor\gql-0.2.0\wandb_gql\client.py", line 60, in _get_result
    return self.transport.execute(document, *args, **kwargs)
  File "C:\Users\sazegar\AppData\Local\Programs\Python\Python38\lib\site-packages\wandb\sdk\lib\gql_request.py", line 59, in execute
    request.raise_for_status()
  File "C:\Users\sazegar\AppData\Local\Programs\Python\Python38\lib\site-packages\requests\models.py", line 1021, in raise_for_status
    raise HTTPError(http_error_msg, response=self)
requests.exceptions.HTTPError: 403 Client Error: Forbidden for url: https://api.wandb.ai/graphql

During handling of the above exception, another exception occurred:

Traceback (most recent call last):
  File "C:\Users\sazegar\AppData\Local\Programs\Python\Python38\lib\site-packages\wandb\sdk\internal\sender.py", line 948, in send_run
    self._init_run(run, config_value_dict)
  File "C:\Users\sazegar\AppData\Local\Programs\Python\Python38\lib\site-packages\wandb\sdk\internal\sender.py", line 990, in _init_run
    server_run, inserted, server_messages = self._api.upsert_run(
  File "C:\Users\sazegar\AppData\Local\Programs\Python\Python38\lib\site-packages\wandb\apis\normalize.py", line 73, in wrapper
    raise err
  File "C:\Users\sazegar\AppData\Local\Programs\Python\Python38\lib\site-packages\wandb\apis\normalize.py", line 41, in wrapper
    return func(*args, **kwargs)
  File "C:\Users\sazegar\AppData\Local\Programs\Python\Python38\lib\site-packages\wandb\sdk\internal\internal_api.py", line 2159, in upsert_run
    self.server_settings_introspection()
  File "C:\Users\sazegar\AppData\Local\Programs\Python\Python38\lib\site-packages\wandb\apis\normalize.py", line 73, in wrapper
    raise err
  File "C:\Users\sazegar\AppData\Local\Programs\Python\Python38\lib\site-packages\wandb\apis\normalize.py", line 41, in wrapper
    return func(*args, **kwargs)
  File "C:\Users\sazegar\AppData\Local\Programs\Python\Python38\lib\site-packages\wandb\sdk\internal\internal_api.py", line 585, in server_settings_introspection
    res = self.gql(query)
  File "C:\Users\sazegar\AppData\Local\Programs\Python\Python38\lib\site-packages\wandb\sdk\internal\internal_api.py", line 341, in gql
    ret = self._retry_gql(
  File "C:\Users\sazegar\AppData\Local\Programs\Python\Python38\lib\site-packages\wandb\sdk\lib\retry.py", line 147, in __call__
    retry_timedelta_triggered = check_retry_fn(e)
  File "C:\Users\sazegar\AppData\Local\Programs\Python\Python38\lib\site-packages\wandb\util.py", line 910, in no_retry_auth
    raise CommError(
wandb.errors.CommError: It appears that you do not have permission to access the requested resource. Please reach out to the project owner to grant you access. If you have the correct permissions, verify that there are no issues with your networking setup.(Error 403: Forbidden)
2024-04-08 06:48:51,114 DEBUG   HandlerThread:16344 [handler.py:handle_request():146] handle_request: shutdown
2024-04-08 06:48:51,114 INFO    HandlerThread:16344 [handler.py:finish():869] shutting down handler
2024-04-08 06:48:51,572 INFO    WriterThread:16344 [datastore.py:close():296] close: C:\Users\sazegar\mir\logic\core\wandb\run-20240408_064850-woc89rfs\run-woc89rfs.wandb
2024-04-08 06:48:52,038 INFO    SenderThread:16344 [sender.py:finish():1521] shutting down sender
